<?xml version="1.0" encoding="utf-8"?>
<!-- This URDF was automatically created by SolidWorks to URDF Exporter! Originally created by Stephen Brawner (brawner@gmail.com) 
     Commit Version: 1.6.0-1-g15f4949  Build Version: 1.6.7594.29634
     For more information, please see http://wiki.ros.org/sw_urdf_exporter -->
<robot
  name="HD15">
 <link name="world"/>
  <link name="base_link">
    <inertial>
      <origin
        xyz="4.15198377587444E-09 0.00600805147496701 0.0154110766377321"
        rpy="0 0 0" />
      <mass
        value="0.225048338313955" />
      <inertia
        ixx="3.0"
        ixy="3.0"
        ixz="3.0"
        iyy="3.0"
        iyz="3.0"
        izz="3.0" />
    </inertial>
    <visual>
      <origin
        xyz="0 0 0"
        rpy="0 0 0" />
      <geometry>
        <mesh
          filename="package://HD15/meshes/base_link.STL" />
      </geometry>
      <material
        name="">
        <color
          rgba="0.792156862745098 0.819607843137255 0.933333333333333 1" />
      </material>
    </visual>
    <collision>
      <origin
        xyz="0 0 0"
        rpy="0 0 0" />
      <geometry>
        <mesh
          filename="package://HD15/meshes/base_link.STL" />
      </geometry>
    </collision>
  </link>
  <joint name="fixed_base_joint" type="fixed">
    <parent link="world"/>
    <child link="base_link"/>
  </joint>
  <link
    name="Link_B">
    <inertial>
      <origin
        xyz="2.33121475821239E-06 0.0133974549441221 -0.00113959391343854"
        rpy="0 0 0" />
      <mass
        value="0.195776104192155" />
      <inertia
        ixx="0.00037151158802518"
        ixy="3.57391770255336E-09"
        ixz="-1.14510206503241E-08"
        iyy="0.000260641810434184"
        iyz="-6.47724249845848E-05"
        izz="0.000369007601869207" />
    </inertial>
    <visual>
      <origin
        xyz="0 0 0"
        rpy="0 0 0" />
      <geometry>
        <mesh
          filename="package://HD15/meshes/Link_B.STL" />
      </geometry>
      <material
        name="">
        <color
          rgba="0.792156862745098 0.819607843137255 0.933333333333333 1" />
      </material>
    </visual>
    <collision>
      <origin
        xyz="0 0 0"
        rpy="0 0 0" />
      <geometry>
        <mesh
          filename="package://HD15/meshes/Link_B.STL" />
      </geometry>
    </collision>
  </link>
  <joint
    name="Joint_B"
    type="revolute">
    <origin
      xyz="0 -6.3732E-05 0.057"
      rpy="0 0 0" />
    <parent
      link="base_link" />
    <child
      link="Link_B" />
    <axis
      xyz="0 0 1" />
    <limit
      lower="-3.14"
      upper="3.14"
      effort="0"
      velocity="0" />
  </joint>
  <link
    name="Link_L">
    <inertial>
      <origin
        xyz="-0.000560859740205511 0.00533997118052245 0.213660387419357"
        rpy="0 0 0" />
      <mass
        value="0.321188945587439" />
      <inertia
        ixx="0.0118715691832119"
        ixy="-9.81413327417368E-07"
        ixz="-3.88389552753312E-05"
        iyy="0.0120340387983652"
        iyz="-0.000369407889610094"
        izz="0.000519207054090904" />
    </inertial>
    <visual>
      <origin
        xyz="0 0 0"
        rpy="0 0 0" />
      <geometry>
        <mesh
          filename="package://HD15/meshes/Link_L.STL" />
      </geometry>
      <material
        name="">
        <color
          rgba="0.792156862745098 0.819607843137255 0.933333333333333 1" />
      </material>
    </visual>
    <collision>
      <origin
        xyz="0 0 0"
        rpy="0 0 0" />
      <geometry>
        <mesh
          filename="package://HD15/meshes/Link_L.STL" />
      </geometry>
    </collision>
  </link>
  <joint
    name="Joint_L"
    type="revolute">
    <origin
      xyz="0 6.37316895830578E-05 0.0620000000000001"
      rpy="0 0 0" />
    <parent
      link="Link_B" />
    <child
      link="Link_L" />
    <axis
      xyz="1 0 0" />
    <limit
      lower="-3.14"
      upper="3.14"
      effort="0"
      velocity="0" />
  </joint>
  <link
    name="Link_U">
    <inertial>
      <origin
        xyz="-0.000125159345751575 0.000986274085085861 0.178341257593513"
        rpy="0 0 0" />
      <mass
        value="0.206991170097614" />
      <inertia
        ixx="0.00313671170173883"
        ixy="-2.56428079267485E-08"
        ixz="-4.62041167196231E-06"
        iyy="0.00320425189687694"
        iyz="-2.4732756309112E-05"
        izz="0.000309068037644153" />
    </inertial>
    <visual>
      <origin
        xyz="0 0 0"
        rpy="0 0 0" />
      <geometry>
        <mesh
          filename="package://HD15/meshes/Link_U.STL" />
      </geometry>
      <material
        name="">
        <color
          rgba="0.792156862745098 0.819607843137255 0.933333333333333 1" />
      </material>
    </visual>
    <collision>
      <origin
        xyz="0 0 0"
        rpy="0 0 0" />
      <geometry>
        <mesh
          filename="package://HD15/meshes/Link_U.STL" />
      </geometry>
    </collision>
  </link>
  <joint
    name="Joint_U"
    type="revolute">
    <origin
      xyz="0 0 0.49000000000015"
      rpy="0 0 0" />
    <parent
      link="Link_L" />
    <child
      link="Link_U" />
    <axis
      xyz="-1 0 0" />
    <limit
      lower="-3.14"
      upper="3.14"
      effort="0"
      velocity="0" />
  </joint>
  <link
    name="Link_W1">
    <inertial>
      <origin
        xyz="-0.00557586157315859 3.06248505948107E-06 0.0481221096166089"
        rpy="0 0 0" />
      <mass
        value="0.15853707936973" />
      <inertia
        ixx="0.00084946148759409"
        ixy="1.0487090997576E-08"
        ixz="4.00351910340966E-05"
        iyy="0.00042085853484323"
        iyz="-2.16190125140588E-08"
        izz="0.000579515182746005" />
    </inertial>
    <visual>
      <origin
        xyz="0 0 0"
        rpy="0 0 0" />
      <geometry>
        <mesh
          filename="package://HD15/meshes/Link_W1.STL" />
      </geometry>
      <material
        name="">
        <color
          rgba="0.792156862745098 0.819607843137255 0.933333333333333 1" />
      </material>
    </visual>
    <collision>
      <origin
        xyz="0 0 0"
        rpy="0 0 0" />
      <geometry>
        <mesh
          filename="package://HD15/meshes/Link_W1.STL" />
      </geometry>
    </collision>
  </link>
  <joint
    name="Joint_W1"
    type="revolute">
    <origin
      xyz="-2.21415510546635E-05 0 0.327050000000298"
      rpy="0 0 0" />
    <parent
      link="Link_U" />
    <child
      link="Link_W1" />
    <axis
      xyz="0 0 -1" />
    <limit
      lower="-3.14"
      upper="3.14"
      effort="0"
      velocity="0" />
  </joint>
  <link
    name="Link_W2">
    <inertial>
      <origin
        xyz="1.13708146428542E-06 1.05864642315289E-07 -0.0029522829617743"
        rpy="0 0 0" />
      <mass
        value="0.198832886498719" />
      <inertia
        ixx="0.000363699833418115"
        ixy="5.4618053031833E-11"
        ixz="-2.89818886510803E-09"
        iyy="9.02807593331075E-05"
        iyz="1.81086096374364E-09"
        izz="0.000317706571914307" />
    </inertial>
    <visual>
      <origin
        xyz="0 0 0"
        rpy="0 0 0" />
      <geometry>
        <mesh
          filename="package://HD15/meshes/Link_W2.STL" />
      </geometry>
      <material
        name="">
        <color
          rgba="0.792156862745098 0.819607843137255 0.933333333333333 1" />
      </material>
    </visual>
    <collision>
      <origin
        xyz="0 0 0"
        rpy="0 0 0" />
      <geometry>
        <mesh
          filename="package://HD15/meshes/Link_W2.STL" />
      </geometry>
    </collision>
  </link>
  <joint
    name="Joint_W2"
    type="revolute">
    <origin
      xyz="0.00377214155074418 0 0.10600000000038"
      rpy="0 0 0" />
    <parent
      link="Link_W1" />
    <child
      link="Link_W2" />
    <axis
      xyz="0 -1 0" />
    <limit
      lower="-3.14"
      upper="3.14"
      effort="0"
      velocity="0" />
  </joint>
  <link
    name="Link_G">
    <inertial>
      <origin
        xyz="0.00211486063330391 7.9626807220292E-07 0.135118039658178"
        rpy="0 0 0" />
      <mass
        value="0.225799596662121" />
      <inertia
        ixx="0.00128821377222038"
        ixy="1.05323037640045E-09"
        ixz="-1.36546254837585E-05"
        iyy="0.000917295554600868"
        iyz="-7.80189175963587E-07"
        izz="0.000432893201445843" />
    </inertial>
    <visual>
      <origin
        xyz="0 0 0"
        rpy="0 0 0" />
      <geometry>
        <mesh
          filename="package://HD15/meshes/Link_G.STL" />
      </geometry>
      <material
        name="">
        <color
          rgba="0.792156862745098 0.819607843137255 0.933333333333333 1" />
      </material>
    </visual>
    <collision>
      <origin
        xyz="0 0 0"
        rpy="0 0 0" />
      <geometry>
        <mesh
          filename="package://HD15/meshes/Link_G.STL" />
      </geometry>
    </collision>
  </link>
  <joint
    name="Joint_G"
    type="revolute">
    <origin
      xyz="3.9155227249506E-05 0 0.0468299999993098"
      rpy="0 0 0" />
    <parent
      link="Link_W2" />
    <child
      link="Link_G" />
    <axis
      xyz="0 0 -1" />
    <limit
      lower="-3.14"
      upper="3.14"
      effort="0"
      velocity="0" />
  </joint>
</robot>
